<?xml version="1.0"?>
<robot name="arm" xmlns:xacro="http://www.ros.org/wiki/xacro">

  <!--Base Footprint-->
  <link name="base_link">
  </link>

  <!--Base link-->
  <link name="base">
    <!-- Visual representation -->
    <visual>
      <origin xyz="0 0 0" rpy="0 0 0"/>
      <geometry>
        <box size="0.5 0.5 0.1"/> 
      </geometry>
    </visual>
    
    <!-- Collision representation -->
    <collision>
      <origin xyz="0 0 0" rpy="0 0 0"/>
      <geometry>
        <box size="0.5 0.5 0.1"/>  
      </geometry>
    </collision>
    
    <!-- Inertial properties -->
    <inertial>
      <origin xyz="0 0 0" rpy="0 0 0"/>
      <mass value="100.0"/>
      <inertia
        ixx="0.5" ixy="0.0" ixz="0.0"
        iyy="0.5" iyz="0.0"
        izz="0.1"/>
    </inertial>
  </link>
  <joint name="base_joint" type="fixed">
    <origin rpy="0 0 0" xyz="0 0 0.05" />
    <parent link="base_link" />
    <child link="base" />
  </joint>


  <!-- Arm 1 -->
  <link name="arm1">
    <visual>
      <origin xyz="0 0 0.5" rpy="0 0 0"/>
      <geometry>
        <box size="0.1 0.05 1.0"/> 
      </geometry>
    </visual>
    <collision>
      <origin xyz="0 0 0.5" rpy="0 0 0"/>
      <geometry>
        <box size="0.1 0.05 1.0"/>  
      </geometry>
    </collision>
    <inertial>
      <origin xyz="0 0 0.5" rpy="0 0 0"/>
      <mass value="1.0"/>
      <inertia
        ixx="0.1" ixy="0.0" ixz="0.0"
        iyy="0.05" iyz="0.0"
        izz="1.0"/>
    </inertial>
  </link>
  <joint name="arm1_joint" type="continuous">
    <origin rpy="0 0 0" xyz="0 0 0.05" />
    <parent link="base" />
    <child link="arm1" />
    <axis xyz="0 0 1" />
  </joint>

  <!-- Arm 2 -->
  <link name="arm2">
    <visual>
      <origin xyz="0 0 0.5" rpy="0 0 0"/>
      <geometry>
        <box size="0.1 0.05 1.0"/> 
      </geometry>
    </visual>
    <collision>
      <origin xyz="0 0 0.5" rpy="0 0 0"/>
      <geometry>
        <box size="0.1 0.05 1.0"/>  
      </geometry>
    </collision>
    <inertial>
      <origin xyz="0 0 0.5" rpy="0 0 0"/>
      <mass value="1.0"/>
      <inertia
        ixx="0.1" ixy="0.0" ixz="0.0"
        iyy="0.05" iyz="0.0"
        izz="1.0"/>
    </inertial>
  </link>
  <joint name="arm2_joint" type="continuous">
    <origin rpy="0 0 0" xyz="0 0.05 1.0" />
    <parent link="arm1" />
    <child link="arm2" />
    <axis xyz="0 1 0" />
  </joint>
</robot>